<?xml version="1.0" ?>
<!-- =================================================================================== -->
<!-- |    This document was autogenerated by xacro from doq.xacro                      | -->
<!-- |    EDITING THIS FILE BY HAND IS NOT RECOMMENDED                                 | -->
<!-- =================================================================================== -->
<mujoco model="twist">
  <!-- XACRO PARAMETERS -->
  <!-- rando stuff -->
  <!-- Body parameters -->
  <!--INERTIA PROB TOO HIGH, maybe make this a pointish mass-->
  <!-- but is it tho -->
  <!-- update -->
  <!-- but is it tho -->
  <!--GTT: Grand Theft Toe-->
  <!-- XACRO MACROS -->
  <compiler angle="radian" autolimits="true"/>
  <option gravity="0 0 -9.81" timestep="0.001">
    <!-- https://github.com/deepmind/mujoco/issues/941 -->
    <flag contact="enable" energy="enable" sensornoise="enable"/>
  </option>
  <default>
    <geom conaffinity="0" contype="4"/>
    <!-- condim='1' solref='0.005 1' solimp ="0.9 0.95 0.001 0.5 2"/>-->
  </default>
  <asset>
    <texture builtin="gradient" height="512" rgb1="0.3 0.5 0.7" rgb2="0 0 0" type="skybox" width="512"/>
    <texture builtin="checker" height="512" mark="cross" markrgb=".8 .8 .8" name="texplane" rgb1=".2 .3 .4" rgb2=".1 0.15 0.2" type="2d" width="512"/>
    <texture builtin="flat" height="1278" mark="cross" markrgb="1 1 1" name="texgeom" random="0.01" rgb1="0.8 0.6 0.4" rgb2="0.8 0.6 0.4" type="cube" width="127"/>
    <material name="matplane" reflectance="0.3" texrepeat="1 1" texture="texplane" texuniform="true"/>
    <material name="matgeom" rgba="0.8 0.6 .4 1" texture="texgeom" texuniform="true"/>
  </asset>
  <worldbody>
    <geom conaffinity="4" contype="2" material="matplane" name="floor" pos="0 0 0" size="0 0 .25" type="plane"/>
    <light cutoff="100" diffuse="1 1 1" dir="-0 0 -1.3" directional="true" exponent="1" pos="0 0 1.3" specular=".1 .1 .1"/>
    <body name="body">
      <joint name="FLOATING" type="free" />
      <geom mass="0.67" name="kinegamiAndBoards" pos="0 0 0" rgba="0.88 0.88 0.88 1.0" size="0.14 0.109 0.015" type="box"/>
      <!-- front_back_sign:=1 left_right_sign:=1" -->
      <body name="hip_0" pos="0.125 0.094 0.0">
        <geom mass="0.21" name="hip_motor_0" pos="0 0.03 0" quat="0.707107 0.707107 0 0" rgba="0 0 1.0 1" size="0.03 0.0125" type="cylinder"/>
        <body name="thigh_0" pos="0 0 0" quat=" 0.9659258 0 0.258819 0">
          <joint axis="0 1 0" damping="0.02" name="HIP0" pos="0 0 0" range="-1.5707963 1.5707963"/>
          <geom mass="0.015" name="thigh_0" pos="0 0 -0.05" rgba="0.8 0.8 0.8 1" size="0.015 0.015 0.05" type="box"/>
          <geom mass="0.21" name="knee_motor_0" pos="0 -0.03 -0.1" quat="0.707107 0.707107 0 0" rgba="0 1.0 0 1" size="0.03 0.0125" type="cylinder"/>
          <body name="shin_0" pos="0 0 -0.1" quat="0.86603 0 -0.5 0">
            <joint axis="0 1 0" damping="0.02" name="KNEE0" pos="0 0 0" range="-1.5707963 1.5707963"/>
            <geom mass="0.015" name="shin_0" pos="0 0 -0.05" rgba="0.8 0.8 0.8 1" size="0.015 0.015 0.05" type="box"/>
            <geom contype="4" mass="0.03" name="toe_0" pos="0 0 -0.1 " quat="0.707107 0.707107 0 0" rgba="0.5 0.5 0.5 1" size="0.015 0.0525" type="cylinder"/>
          </body>
        </body>
      </body>
      <!-- front_back_sign:=1 left_right_sign:=1" -->
      <body name="hip_1" pos="-0.125 0.094 0.0">
        <geom mass="0.21" name="hip_motor_1" pos="0 0.03 0" quat="0.707107 0.707107 0 0" rgba="0 0 0.6699999999999999 1" size="0.03 0.0125" type="cylinder"/>
        <body name="thigh_1" pos="0 0 0" quat=" 0.9659258 0 0.258819 0">
          <joint axis="0 1 0" damping="0.02" name="HIP1" pos="0 0 0" range="-1.5707963 1.5707963"/>
          <geom mass="0.015" name="thigh_1" pos="0 0 -0.05" rgba="0.8 0.8 0.8 1" size="0.015 0.015 0.05" type="box"/>
          <geom mass="0.21" name="knee_motor_1" pos="0 -0.03 -0.1" quat="0.707107 0.707107 0 0" rgba="0 0.6699999999999999 0 1" size="0.03 0.0125" type="cylinder"/>
          <body name="shin_1" pos="0 0 -0.1" quat="0.86603 0 -0.5 0">
            <joint axis="0 1 0" damping="0.02" name="KNEE1" pos="0 0 0" range="-1.5707963 1.5707963"/>
            <geom mass="0.015" name="shin_1" pos="0 0 -0.05" rgba="0.8 0.8 0.8 1" size="0.015 0.015 0.05" type="box"/>
            <geom contype="4" mass="0.03" name="toe_1" pos="0 0 -0.1 " quat="0.707107 0.707107 0 0" rgba="0.5 0.5 0.5 1" size="0.015 0.0525" type="cylinder"/>
          </body>
        </body>
      </body>
      <!-- front_back_sign:=1 left_right_sign:=1" -->
      <body name="hip_2" pos="0.125 -0.094 0.0">
        <geom mass="0.21" name="hip_motor_2" pos="0 -0.03 0" quat="0.707107 0.707107 0 0" rgba="0 0 0.33999999999999997 1" size="0.03 0.0125" type="cylinder"/>
        <body name="thigh_2" pos="0 0 0" quat=" 0.9659258 0 0.258819 0">
          <joint axis="0 1 0" damping="0.02" name="HIP2" pos="0 0 0" range="-1.5707963 1.5707963"/>
          <geom mass="0.015" name="thigh_2" pos="0 0 -0.05" rgba="0.8 0.8 0.8 1" size="0.015 0.015 0.05" type="box"/>
          <geom mass="0.21" name="knee_motor_2" pos="0 0.03 -0.1" quat="0.707107 0.707107 0 0" rgba="0 0.33999999999999997 0 1" size="0.03 0.0125" type="cylinder"/>
          <body name="shin_2" pos="0 0 -0.1" quat="0.86603 0 -0.5 0">
            <joint axis="0 1 0" damping="0.02" name="KNEE2" pos="0 0 0" range="-1.5707963 1.5707963"/>
            <geom mass="0.015" name="shin_2" pos="0 0 -0.05" rgba="0.8 0.8 0.8 1" size="0.015 0.015 0.05" type="box"/>
            <geom contype="4" mass="0.03" name="toe_2" pos="0 0 -0.1 " quat="0.707107 0.707107 0 0" rgba="0.5 0.5 0.5 1" size="0.015 0.0525" type="cylinder"/>
          </body>
        </body>
      </body>
      <!-- front_back_sign:=1 left_right_sign:=1" -->
      <body name="hip_3" pos="-0.125 -0.094 0.0">
        <geom mass="0.21" name="hip_motor_3" pos="0 -0.03 0" quat="0.707107 0.707107 0 0" rgba="0 0 0.010000000000000009 1" size="0.03 0.0125" type="cylinder"/>
        <body name="thigh_3" pos="0 0 0" quat=" 0.9659258 0 0.258819 0">
          <joint axis="0 1 0" damping="0.02" name="HIP3" pos="0 0 0" range="-1.5707963 1.5707963"/>
          <geom mass="0.015" name="thigh_3" pos="0 0 -0.05" rgba="0.8 0.8 0.8 1" size="0.015 0.015 0.05" type="box"/>
          <geom mass="0.21" name="knee_motor_3" pos="0 0.03 -0.1" quat="0.707107 0.707107 0 0" rgba="0 0.010000000000000009 0 1" size="0.03 0.0125" type="cylinder"/>
          <body name="shin_3" pos="0 0 -0.1" quat="0.86603 0 -0.5 0">
            <joint axis="0 1 0" damping="0.02" name="KNEE3" pos="0 0 0" range="-1.5707963 1.5707963"/>
            <geom mass="0.015" name="shin_3" pos="0 0 -0.05" rgba="0.8 0.8 0.8 1" size="0.015 0.015 0.05" type="box"/>
            <geom contype="4" mass="0.03" name="toe_3" pos="0 0 -0.1 " quat="0.707107 0.707107 0 0" rgba="0.5 0.5 0.5 1" size="0.015 0.0525" type="cylinder"/>
          </body>
        </body>
      </body>
      <site name="IMU" quat="0 0 1 0"/>
      <!-- quat cuz reorienting IMU to match (i think) real life moteus pi3hat imu orientation-->
      <!-- <site name="IMU"/> -->
    </body>
  </worldbody>
  <actuator>
    <general joint="HIP0" name="HIP0_act" forcelimited="true" forcerange="-2 2" ctrlrange="-1 1" gainprm="1000 0 0"/>
    <general joint="KNEE0" name="KNEE0_act" forcelimited="true" forcerange="-2 2" ctrlrange="-1 1" gainprm="1000 0 0"/>
    <general joint="HIP1" name="HIP1_act" forcelimited="true" forcerange="-2 2" ctrlrange="-1 1" gainprm="1000 0 0"/>
    <general joint="KNEE1" name="KNEE1_act" forcelimited="true" forcerange="-2 2" ctrlrange="-1 1" gainprm="1000 0 0"/>
    <general joint="HIP2" name="HIP2_act" forcelimited="true" forcerange="-2 2" ctrlrange="-1 1" gainprm="1000 0 0"/>
    <general joint="KNEE2" name="KNEE2_act" forcelimited="true" forcerange="-2 2" ctrlrange="-1 1" gainprm="1000 0 0"/>
    <general joint="HIP3" name="HIP3_act" forcelimited="true" forcerange="-2 2" ctrlrange="-1 1" gainprm="1000 0 0"/>
    <general joint="KNEE3" name="KNEE3_act" forcelimited="true" forcerange="-2 2" ctrlrange="-1 1" gainprm="1000 0 0"/>
  </actuator>
  <sensor>
    <accelerometer name="ACCEL" site="IMU"/>
    <gyro name="GYRO" site="IMU"/>
    <framequat name="QUAT" objname="IMU" objtype="site"/>
    <!-- <subtreecom name="COM" body="base"/> -->
  </sensor>
</mujoco>
